Workbook

Sheet Part A
A1: ID | B1: first_name | C1: last_name | D1: email | E1: gender | F1: Race | G1: purchase | H1: credit_card_type | I1: date | J1: State/Province | K1: City | L1: PostalCode | M1: Country | N1: UserName | O1: CompanyName | P1: JobTitle | Q1: FullName
A2: 16 | B2: Lois | C2: Fowler | D2: lfowlerf@seattletimes.com | E2: Female | F2: White | G2: 15 | H2: jcb | I2: 44494 | J2: Minnesota | K2: Saint Paul | L2: 55123 | M2: United States | N2: =VLOOKUP(A2, Data_Set_2!$A:$D,2,FALSE) -> lfowlerf | O2: =VLOOKUP(A2, Data_Set_2!$A:$D,3,FALSE) -> Roomm | P2: =VLOOKUP(A2, Data_Set_2!$A:$D,4,FALSE) -> Financial Analyst | Q2: =_xlfn.CONCAT(Table3[[#This Row],[first_name]], " ",Table3[[#This Row],[last_name]]) -> Lois Fowler
A3: 17 | B3: Tammy | C3: Spencer | D3: tspencerg@istockphoto.com | E3: Female | F3: Black or African American | G3: 143 | H3: jcb | I3: 43751 | J3: Delaware | K3: Newark | L3: 19725 | M3: United States | N3: =VLOOKUP(A3, Data_Set_2!$A:$D,2,FALSE) -> tspencerg | O3: =VLOOKUP(A3, Data_Set_2!$A:$D,3,FALSE) -> Photolist | P3: =VLOOKUP(A3, Data_Set_2!$A:$D,4,FALSE) -> Account Coordinator | Q3: =_xlfn.CONCAT(Table3[[#This Row],[first_name]], " ",Table3[[#This Row],[last_name]]) -> Tammy Spencer
A4: 18 | B4: Douglas | C4: Daniels | D4: ddanielsh@cam.ac.uk | E4: Male | F4: White | G4: 134 | H4: jcb | I4: 43950 | J4: Ohio | K4: Dayton | L4: 45454 | M4: United States | N4: =VLOOKUP(A4, Data_Set_2!$A:$D,2,FALSE) -> ddanielsh | O4: =VLOOKUP(A4, Data_Set_2!$A:$D,3,FALSE) -> Gabcube | P4: =VLOOKUP(A4, Data_Set_2!$A:$D,4,FALSE) -> Safety Technician II | Q4: =_xlfn.CONCAT(Table3[[#This Row],[first_name]], " ",Table3[[#This Row],[last_name]]) -> Douglas Daniels
A5: 18 | B5: Douglas | C5: Daniels | D5: ddanielsh@cam.ac.uk | E5: Male | F5: White | G5: 20 | H5: jcb | I5: 44076 | J5: Ohio | K5: Dayton | L5: 45454 | M5: United States | N5: =VLOOKUP(A5, Data_Set_2!$A:$D,2,FALSE) -> ddanielsh | O5: =VLOOKUP(A5, Data_Set_2!$A:$D,3,FALSE) -> Gabcube | P5: =VLOOKUP(A5, Data_Set_2!$A:$D,4,FALSE) -> Safety Technician II | Q5: =_xlfn.CONCAT(Table3[[#This Row],[first_name]], " ",Table3[[#This Row],[last_name]]) -> Douglas Daniels
A6: 18 | B6: Douglas | C6: Daniels | D6: ddanielsh@cam.ac.uk | E6: Male | F6: White | G6: 593 | H6: jcb | I6: 44475 | J6: Ohio | K6: Dayton | L6: 45454 | M6: United States | N6: =VLOOKUP(A6, Data_Set_2!$A:$D,2,FALSE) -> ddanielsh | O6: =VLOOKUP(A6, Data_Set_2!$A:$D,3,FALSE) -> Gabcube | P6: =VLOOKUP(A6, Data_Set_2!$A:$D,4,FALSE) -> Safety Technician II | Q6: =_xlfn.CONCAT(Table3[[#This Row],[first_name]], " ",Table3[[#This Row],[last_name]]) -> Douglas Daniels
A7: 20 | B7: Maria | C7: Hart | D7: mhartj@intel.com | E7: Female | F7: South American | G7: 410 | H7: switch | I7: 44021 | J7: Florida | K7: Miami | L7: 33196 | M7: United States | N7: =VLOOKUP(A7, Data_Set_2!$A:$D,2,FALSE) -> mhartj | O7: =VLOOKUP(A7, Data_Set_2!$A:$D,3,FALSE) -> Dynabox | P7: =VLOOKUP(A7, Data_Set_2!$A:$D,4,FALSE) -> Human Resources Assistant III | Q7: =_xlfn.CONCAT(Table3[[#This Row],[first_name]], " ",Table3[[#This Row],[last_name]]) -> Maria Hart
A8: 21 | B8: Mary | C8: Ward | D8: mwardk@arizona.edu | E8: Female | F8: Black or African American | G8: 488 | H8: jcb | I8: 43196 | J8: Connecticut | K8: Hartford | L8: 6152 | M8: United States | N8: =VLOOKUP(A8, Data_Set_2!$A:$D,2,FALSE) -> mwardk | O8: =VLOOKUP(A8, Data_Set_2!$A:$D,3,FALSE) -> Skibox | P8: =VLOOKUP(A8, Data_Set_2!$A:$D,4,FALSE) -> Assistant Manager | Q8: =_xlfn.CONCAT(Table3[[#This Row],[first_name]], " ",Table3[[#This Row],[last_name]]) -> Mary Ward
A9: 22 | B9: Rose | C9: Perez | D9: rperezl@boston.com | E9: Female | F9: Black or African American | G9: 11 | H9: jcb | I9: 43587 | J9: Nevada | K9: Reno | L9: 89505 | M9: United States | N9: =VLOOKUP(A9, Data_Set_2!$A:$D,2,FALSE) -> rperezl | O9: =VLOOKUP(A9, Data_Set_2!$A:$D,3,FALSE) -> Livetube | P9: =VLOOKUP(A9, Data_Set_2!$A:$D,4,FALSE) -> Marketing Assistant | Q9: =_xlfn.CONCAT(Table3[[#This Row],[first_name]], " ",Table3[[#This Row],[last_name]]) -> Rose Perez
A10: 24 | B10: Henry | C10: Warren | D10: hwarrenn@jalbum.net | E10: Male | F10: Black or African American | G10: 266 | H10: diners club carte blanche | I10: 44610 | J10: Pennsylvania | K10: Pittsburgh | L10: 15205 | M10: United States | N10: =VLOOKUP(A10, Data_Set_2!$A:$D,2,FALSE) -> hwarrenn | O10: =VLOOKUP(A10, Data_Set_2!$A:$D,3,FALSE) -> Gabtune | P10: =VLOOKUP(A10, Data_Set_2!$A:$D,4,FALSE) -> Senior Financial Analyst | Q10: =_xlfn.CONCAT(Table3[[#This Row],[first_name]], " ",Table3[[#This Row],[last_name]]) -> Henry Warren
A11: 25 | B11: Janet | C11: Bradley | D11: jbradleyo@shop-pro.jp | E11: Female | F11: Black or African American | G11: 904 | H11: solo | I11: 43247 | J11: Minnesota | K11: Minneapolis | L11: 55448 | M11: United States | N11: =VLOOKUP(A11, Data_Set_2!$A:$D,2,FALSE) -> jbradleyo | O11: =VLOOKUP(A11, Data_Set_2!$A:$D,3,FALSE) -> Edgeify | P11: =VLOOKUP(A11, Data_Set_2!$A:$D,4,FALSE) -> VP Marketing | Q11: =_xlfn.CONCAT(Table3[[#This Row],[first_name]], " ",Table3[[#This Row],[last_name]]) -> Janet Bradley
A12: 25 | B12: Janet | C12: Bradley | D12: jbradleyo@shop-pro.jp | E12: Female | F12: Black or African American | G12: 886 | H12: solo | I12: 43309 | J12: Minnesota | K12: Minneapolis | L12: 55448 | M12: United States | N12: =VLOOKUP(A12, Data_Set_2!$A:$D,2,FALSE) -> jbradleyo | O12: =VLOOKUP(A12, Data_Set_2!$A:$D,3,FALSE) -> Edgeify | P12: =VLOOKUP(A12, Data_Set_2!$A:$D,4,FALSE) -> VP Marketing | Q12: =_xlfn.CONCAT(Table3[[#This Row],[first_name]], " ",Table3[[#This Row],[last_name]]) -> Janet Bradley
A13: 25 | B13: Janet | C13: Bradley | D13: jbradleyo@shop-pro.jp | E13: Female | F13: Black or African American | G13: 905 | H13: solo | I13: 43310 | J13: Minnesota | K13: Minneapolis | L13: 55448 | M13: United States | N13: =VLOOKUP(A13, Data_Set_2!$A:$D,2,FALSE) -> jbradleyo | O13: =VLOOKUP(A13, Data_Set_2!$A:$D,3,FALSE) -> Edgeify | P13: =VLOOKUP(A13, Data_Set_2!$A:$D,4,FALSE) -> VP Marketing | Q13: =_xlfn.CONCAT(Table3[[#This Row],[first_name]], " ",Table3[[#This Row],[last_name]]) -> Janet Bradley
... A16: 25 | B16: Janet | C16: Bradley | D16: jbradleyo@shop-pro.jp | E16: Female | F16: Black or African American | G16: 174 | H16: solo | I16: 43403 | J16: Minnesota | K16: Minneapolis | L16: 55448 | M16: United States | N16: =VLOOKUP(A16, Data_Set_2!$A:$D,2,FALSE) -> jbradleyo | O16: =VLOOKUP(A16, Data_Set_2!$A:$D,3,FALSE) -> Edgeify | P16: =VLOOKUP(A16, Data_Set_2!$A:$D,4,FALSE) -> VP Marketing | Q16: =_xlfn.CONCAT(Table3[[#This Row],[first_name]], " ",Table3[[#This Row],[last_name]]) -> Janet Bradley
A17: 25 | B17: Janet | C17: Bradley | D17: jbradleyo@shop-pro.jp | E17: Female | F17: Black or African American | G17: 893 | H17: solo | I17: 2/29/2019 | J17: Minnesota | K17: Minneapolis | L17: 55448 | M17: United States | N17: =VLOOKUP(A17, Data_Set_2!$A:$D,2,FALSE) -> jbradleyo | O17: =VLOOKUP(A17, Data_Set_2!$A:$D,3,FALSE) -> Edgeify | P17: =VLOOKUP(A17, Data_Set_2!$A:$D,4,FALSE) -> VP Marketing | Q17: =_xlfn.CONCAT(Table3[[#This Row],[first_name]], " ",Table3[[#This Row],[last_name]]) -> Janet Bradley
A18: 25 | B18: Janet | C18: Bradley | D18: jbradleyo@shop-pro.jp | E18: Female | F18: Black or African American | G18: 517 | H18: solo | I18: 43561 | J18: Minnesota | K18: Minneapolis | L18: 55448 | M18: United States | N18: =VLOOKUP(A18, Data_Set_2!$A:$D,2,FALSE) -> jbradleyo | O18: =VLOOKUP(A18, Data_Set_2!$A:$D,3,FALSE) -> Edgeify | P18: =VLOOKUP(A18, Data_Set_2!$A:$D,4,FALSE) -> VP Marketing | Q18: =_xlfn.CONCAT(Table3[[#This Row],[first_name]], " ",Table3[[#This Row],[last_name]]) -> Janet Bradley
A19: 25 | B19: Janet | C19: Bradley | D19: jbradleyo@shop-pro.jp | E19: Female | F19: Black or African American | G19: 990 | H19: solo | I19: 43629 | J19: Minnesota | K19: Minneapolis | L19: 55448 | M19: United States | N19: =VLOOKUP(A19, Data_Set_2!$A:$D,2,FALSE) -> jbradleyo | O19: =VLOOKUP(A19, Data_Set_2!$A:$D,3,FALSE) -> Edgeify | P19: =VLOOKUP(A19, Data_Set_2!$A:$D,4,FALSE) -> VP Marketing | Q19: =_xlfn.CONCAT(Table3[[#This Row],[first_name]], " ",Table3[[#This Row],[last_name]]) -> Janet Bradley
A20: 25 | B20: Janet | C20: Bradley | D20: jbradleyo@shop-pro.jp | E20: Female | F20: Black or African American | G20: 824 | H20: solo | I20: 43753 | J20: Minnesota | K20: Minneapolis | L20: 55448 | M20: United States | N20: =VLOOKUP(A20, Data_Set_2!$A:$D,2,FALSE) -> jbradleyo | O20: =VLOOKUP(A20, Data_Set_2!$A:$D,3,FALSE) -> Edgeify | P20: =VLOOKUP(A20, Data_Set_2!$A:$D,4,FALSE) -> VP Marketing | Q20: =_xlfn.CONCAT(Table3[[#This Row],[first_name]], " ",Table3[[#This Row],[last_name]]) -> Janet Bradley
A21: 25 | B21: Janet | C21: Bradley | D21: jbradleyo@shop-pro.jp | E21: Female | F21: Black or African American | G21: 813 | H21: solo | I21: 43756 | J21: Minnesota | K21: Minneapolis | L21: 55448 | M21: United States | N21: =VLOOKUP(A21, Data_Set_2!$A:$D,2,FALSE) -> jbradleyo | O21: =VLOOKUP(A21, Data_Set_2!$A:$D,3,FALSE) -> Edgeify | P21: =VLOOKUP(A21, Data_Set_2!$A:$D,4,FALSE) -> VP Marketing | Q21: =_xlfn.CONCAT(Table3[[#This Row],[first_name]], " ",Table3[[#This Row],[last_name]]) -> Janet Bradley
A22: 25 | B22: Janet | C22: Bradley | D22: jbradleyo@shop-pro.jp | E22: Female | F22: Black or African American | G22: 696 | H22: solo | I22: 43760 | J22: Minnesota | K22: Minneapolis | L22: 55448 | M22: United States | N22: =VLOOKUP(A22, Data_Set_2!$A:$D,2,FALSE) -> jbradleyo | O22: =VLOOKUP(A22, Data_Set_2!$A:$D,3,FALSE) -> Edgeify | P22: =VLOOKUP(A22, Data_Set_2!$A:$D,4,FALSE) -> VP Marketing | Q22: =_xlfn.CONCAT(Table3[[#This Row],[first_name]], " ",Table3[[#This Row],[last_name]]) -> Janet Bradley
A23: 25 | B23: Janet | C23: Bradley | D23: jbradleyo@shop-pro.jp | E23: Female | F23: Black or African American | G23: 172 | H23: solo | I23: 43978 | J23: Minnesota | K23: Minneapolis | L23: 55448 | M23: United States | N23: =VLOOKUP(A23, Data_Set_2!$A:$D,2,FALSE) -> jbradleyo | O23: =VLOOKUP(A23, Data_Set_2!$A:$D,3,FALSE) -> Edgeify | P23: =VLOOKUP(A23, Data_Set_2!$A:$D,4,FALSE) -> VP Marketing | Q23: =_xlfn.CONCAT(Table3[[#This Row],[first_name]], " ",Table3[[#This Row],[last_name]]) -> Janet Bradley
A24: 25 | B24: Janet | C24: Bradley | D24: jbradleyo@shop-pro.jp | E24: Female | F24: Black or African American | G24: 573 | H24: solo | I24: 44024 | J24: Minnesota | K24: Minneapolis | L24: 55448 | M24: United States | N24: =VLOOKUP(A24, Data_Set_2!$A:$D,2,FALSE) -> jbradleyo | O24: =VLOOKUP(A24, Data_Set_2!$A:$D,3,FALSE) -> Edgeify | P24: =VLOOKUP(A24, Data_Set_2!$A:$D,4,FALSE) -> VP Marketing | Q24: =_xlfn.CONCAT(Table3[[#This Row],[first_name]], " ",Table3[[#This Row],[last_name]]) -> Janet Bradley
A25: 25 | B25: Janet | C25: Bradley | D25: jbradleyo@shop-pro.jp | E25: Female | F25: Black or African American | G25: 886 | H25: solo | I25: 44047 | J25: Minnesota | K25: Minneapolis | L25: 55448 | M25: United States | N25: =VLOOKUP(A25, Data_Set_2!$A:$D,2,FALSE) -> jbradleyo | O25: =VLOOKUP(A25, Data_Set_2!$A:$D,3,FALSE) -> Edgeify | P25: =VLOOKUP(A25, Data_Set_2!$A:$D,4,FALSE) -> VP Marketing | Q25: =_xlfn.CONCAT(Table3[[#This Row],[first_name]], " ",Table3[[#This Row],[last_name]]) -> Janet Bradley
A26: 25 | B26: Janet | C26: Bradley | D26: jbradleyo@shop-pro.jp | E26: Female | F26: Black or African American | G26: 980 | H26: solo | I26: 44085 | J26: Minnesota | K26: Minneapolis | L26: 55448 | M26: United States | N26: =VLOOKUP(A26, Data_Set_2!$A:$D,2,FALSE) -> jbradleyo | O26: =VLOOKUP(A26, Data_Set_2!$A:$D,3,FALSE) -> Edgeify | P26: =VLOOKUP(A26, Data_Set_2!$A:$D,4,FALSE) -> VP Marketing | Q26: =_xlfn.CONCAT(Table3[[#This Row],[first_name]], " ",Table3[[#This Row],[last_name]]) -> Janet Bradley
A27: 25 | B27: Janet | C27: Bradley | D27: jbradleyo@shop-pro.jp | E27: Female | F27: Black or African American | G27: 256 | H27: solo | I27: 44129 | J27: Minnesota | K27: Minneapolis | L27: 55448 | M27: United States | N27: =VLOOKUP(A27, Data_Set_2!$A:$D,2,FALSE) -> jbradleyo | O27: =VLOOKUP(A27, Data_Set_2!$A:$D,3,FALSE) -> Edgeify | P27: =VLOOKUP(A27, Data_Set_2!$A:$D,4,FALSE) -> VP Marketing | Q27: =_xlfn.CONCAT(Table3[[#This Row],[first_name]], " ",Table3[[#This Row],[last_name]]) -> Janet Bradley
A28: 25 | B28: Janet | C28: Bradley | D28: jbradleyo@shop-pro.jp | E28: Female | F28: Black or African American | G28: 415 | H28: solo | I28: 44315 | J28: Minnesota | K28: Minneapolis | L28: 55448 | M28: United States | N28: =VLOOKUP(A28, Data_Set_2!$A:$D,2,FALSE) -> jbradleyo | O28: =VLOOKUP(A28, Data_Set_2!$A:$D,3,FALSE) -> Edgeify | P28: =VLOOKUP(A28, Data_Set_2!$A:$D,4,FALSE) -> VP Marketing | Q28: =_xlfn.CONCAT(Table3[[#This Row],[first_name]], " ",Table3[[#This Row],[last_name]]) -> Janet Bradley
A29: 25 | B29: Janet | C29: Bradley | D29: jbradleyo@shop-pro.jp | E29: Female | F29: Black or African American | G29: 11 | H29: solo | I29: 44458 | J29: Minnesota | K29: Minneapolis | L29: 55448 | M29: United States | N29: =VLOOKUP(A29, Data_Set_2!$A:$D,2,FALSE) -> jbradleyo | O29: =VLOOKUP(A29, Data_Set_2!$A:$D,3,FALSE) -> Edgeify | P29: =VLOOKUP(A29, Data_Set_2!$A:$D,4,FALSE) -> VP Marketing | Q29: =_xlfn.CONCAT(Table3[[#This Row],[first_name]], " ",Table3[[#This Row],[last_name]]) -> Janet Bradley
... A1396: 1000 | B1396: Jeffrey | C1396: Watson | D1396: jwatsonrr@samsung.com | E1396: Male | F1396: Black or African American | G1396: 38 | H1396: mastercard | I1396: 44279 | J1396: California | K1396: Fresno | L1396: 93726 | M1396: United States | N1396: =VLOOKUP(A1396, Data_Set_2!$A:$D,2,FALSE) -> jwatsonrr | O1396: =VLOOKUP(A1396, Data_Set_2!$A:$D,3,FALSE) -> Buzzbean | P1396: =VLOOKUP(A1396, Data_Set_2!$A:$D,4,FALSE) -> Safety Technician I | Q1396: =_xlfn.CONCAT(Table3[[#This Row],[first_name]], " ",Table3[[#This Row],[last_name]]) -> Jeffrey Watson

Sheet Part B
A1: Part B #1 | B1: Unique Race | C1: # of People Per Race | D1: Part B #2 | E1: Gender | F1: # of People Per Gender | G1: Part B #3 | H1: Race | I1: Male | J1: Female
B2: White | C2: =COUNTIF(Worksheet!$B:$B,B2) -> 295 | E2: Female | F2: =COUNTIF(Worksheet!$C:$C,E2) -> 281 | H2: White | I2: =SUMIFS(Worksheet!$D:$D,Worksheet!$B:$B,Table5[[#This Row],[Race]],Worksheet!$C:$C,Table5[[#Headers],[Male]]) -> 185388 | J2: =SUMIFS(Worksheet!$D:$D,Worksheet!$B:$B,Table5[[#This Row],[Race]],Worksheet!$C:$C,Table5[[#Headers],[Female]]) -> 110592
B3: Black or African American | C3: =COUNTIF(Worksheet!$B:$B,B3) -> 122 | E3: Male | F3: =COUNTIF(Worksheet!$C:$C,E3) -> 277 | H3: Black or African American | I3: =SUMIFS(Worksheet!$D:$D,Worksheet!$B:$B,Table5[[#This Row],[Race]],Worksheet!$C:$C,Table5[[#Headers],[Male]]) -> 88376 | J3: =SUMIFS(Worksheet!$D:$D,Worksheet!$B:$B,Table5[[#This Row],[Race]],Worksheet!$C:$C,Table5[[#Headers],[Female]]) -> 97666
B4: South American | C4: =COUNTIF(Worksheet!$B:$B,B4) -> 4 | H4: South American | I4: =SUMIFS(Worksheet!$D:$D,Worksheet!$B:$B,Table5[[#This Row],[Race]],Worksheet!$C:$C,Table5[[#Headers],[Male]]) -> 197 | J4: =SUMIFS(Worksheet!$D:$D,Worksheet!$B:$B,Table5[[#This Row],[Race]],Worksheet!$C:$C,Table5[[#Headers],[Female]]) -> 2544
B5: Asian | C5: =COUNTIF(Worksheet!$B:$B,B5) -> 82 | H5: Asian | I5: =SUMIFS(Worksheet!$D:$D,Worksheet!$B:$B,Table5[[#This Row],[Race]],Worksheet!$C:$C,Table5[[#Headers],[Male]]) -> 71354 | J5: =SUMIFS(Worksheet!$D:$D,Worksheet!$B:$B,Table5[[#This Row],[Race]],Worksheet!$C:$C,Table5[[#Headers],[Female]]) -> 45119
B6: Mexican | C6: =COUNTIF(Worksheet!$B:$B,B6) -> 34 | H6: Mexican | I6: =SUMIFS(Worksheet!$D:$D,Worksheet!$B:$B,Table5[[#This Row],[Race]],Worksheet!$C:$C,Table5[[#Headers],[Male]]) -> 45235 | J6: =SUMIFS(Worksheet!$D:$D,Worksheet!$B:$B,Table5[[#This Row],[Race]],Worksheet!$C:$C,Table5[[#Headers],[Female]]) -> 34993
B7: Hispanic | C7: =COUNTIF(Worksheet!$B:$B,B7) -> 3 | H7: Hispanic | I7: =SUMIFS(Worksheet!$D:$D,Worksheet!$B:$B,Table5[[#This Row],[Race]],Worksheet!$C:$C,Table5[[#Headers],[Male]]) -> 909 | J7: =SUMIFS(Worksheet!$D:$D,Worksheet!$B:$B,Table5[[#This Row],[Race]],Worksheet!$C:$C,Table5[[#Headers],[Female]]) -> 8503
B8: American Indian | C8: =COUNTIF(Worksheet!$B:$B,B8) -> 2 | H8: American Indian | I8: =SUMIFS(Worksheet!$D:$D,Worksheet!$B:$B,Table5[[#This Row],[Race]],Worksheet!$C:$C,Table5[[#Headers],[Male]]) -> 3831 | J8: =SUMIFS(Worksheet!$D:$D,Worksheet!$B:$B,Table5[[#This Row],[Race]],Worksheet!$C:$C,Table5[[#Headers],[Female]]) -> 0
B9: Taiwanese | C9: =COUNTIF(Worksheet!$B:$B,B9) -> 4 | H9: Taiwanese | I9: =SUMIFS(Worksheet!$D:$D,Worksheet!$B:$B,Table5[[#This Row],[Race]],Worksheet!$C:$C,Table5[[#Headers],[Male]]) -> 2574 | J9: =SUMIFS(Worksheet!$D:$D,Worksheet!$B:$B,Table5[[#This Row],[Race]],Worksheet!$C:$C,Table5[[#Headers],[Female]]) -> 1503
B10: Thai | C10: =COUNTIF(Worksheet!$B:$B,B10) -> 5 | H10: Thai | I10: =SUMIFS(Worksheet!$D:$D,Worksheet!$B:$B,Table5[[#This Row],[Race]],Worksheet!$C:$C,Table5[[#Headers],[Male]]) -> 3145 | J10: =SUMIFS(Worksheet!$D:$D,Worksheet!$B:$B,Table5[[#This Row],[Race]],Worksheet!$C:$C,Table5[[#Headers],[Female]]) -> 1633
B11: Argentinian | C11: =COUNTIF(Worksheet!$B:$B,B11) -> 2 | H11: Argentinian | I11: =SUMIFS(Worksheet!$D:$D,Worksheet!$B:$B,Table5[[#This Row],[Race]],Worksheet!$C:$C,Table5[[#Headers],[Male]]) -> 614 | J11: =SUMIFS(Worksheet!$D:$D,Worksheet!$B:$B,Table5[[#This Row],[Race]],Worksheet!$C:$C,Table5[[#Headers],[Female]]) -> 1338
B12: Costa Rican | C12: =COUNTIF(Worksheet!$B:$B,B12) -> 2 | H12: Costa Rican | I12: =SUMIFS(Worksheet!$D:$D,Worksheet!$B:$B,Table5[[#This Row],[Race]],Worksheet!$C:$C,Table5[[#Headers],[Male]]) -> 0 | J12: =SUMIFS(Worksheet!$D:$D,Worksheet!$B:$B,Table5[[#This Row],[Race]],Worksheet!$C:$C,Table5[[#Headers],[Female]]) -> 1407
B13: Japanese | C13: =COUNTIF(Worksheet!$B:$B,B13) -> 1 | H13: Japanese | I13: =SUMIFS(Worksheet!$D:$D,Worksheet!$B:$B,Table5[[#This Row],[Race]],Worksheet!$C:$C,Table5[[#Headers],[Male]]) -> 0 | J13: =SUMIFS(Worksheet!$D:$D,Worksheet!$B:$B,Table5[[#This Row],[Race]],Worksheet!$C:$C,Table5[[#Headers],[Female]]) -> 3263
B14: Eskimo | C14: =COUNTIF(Worksheet!$B:$B,B14) -> 2 | H14: Eskimo | I14: =SUMIFS(Worksheet!$D:$D,Worksheet!$B:$B,Table5[[#This Row],[Race]],Worksheet!$C:$C,Table5[[#Headers],[Male]]) -> 0 | J14: =SUMIFS(Worksheet!$D:$D,Worksheet!$B:$B,Table5[[#This Row],[Race]],Worksheet!$C:$C,Table5[[#Headers],[Female]]) -> 5614
A16: Equations are also on Worksheet tab
C18: Part B # 4

Sheet Part C
A1: Part C # 1 | B1: Top 5 Customers by # of Purchases | C1: Customer # of Purchases | D1: Part C # 2 | E1: Top 5 Customers by Value of Purchases | F1: Customer Value of Purchases $ | G1: Part C # 3 | H1: Credit Card Company
B2: =INDEX(Worksheet!$A:$A,MATCH(LARGE(Worksheet!$E:$E,1),Worksheet!$E:$E,0)) -> Kenneth Perry | C2: =VLOOKUP(B2,Worksheet!$A:$E,5,FALSE) -> 150 | E2: =INDEX(Worksheet!$A:$A,MATCH(LARGE(Worksheet!$D:$D,1),Worksheet!$D:$D,0)) -> Kenneth Perry | F2: =VLOOKUP(E2,Worksheet!$A:$E,4,FALSE) -> 78731 | H2: =_xlfn.XLOOKUP(E2,'Part A'!$Q:$Q,'Part A'!$H:$H,0,0,1) -> jcb
B3: =INDEX(Worksheet!$A:$A,MATCH(LARGE(Worksheet!$E:$E,2),Worksheet!$E:$E,0)) -> Brandon Jacobs | C3: =VLOOKUP(B3,Worksheet!$A:$E,5,FALSE) -> 49 | E3: =INDEX(Worksheet!$A:$A,MATCH(LARGE(Worksheet!$D:$D,2),Worksheet!$D:$D,0)) -> Brandon Jacobs | F3: =VLOOKUP(E3,Worksheet!$A:$E,4,FALSE) -> 27535 | H3: =_xlfn.XLOOKUP(E3,'Part A'!$Q:$Q,'Part A'!$H:$H,0,0,1) -> maestro
B4: =INDEX(Worksheet!$A:$A,MATCH(LARGE(Worksheet!$E:$E,3),Worksheet!$E:$E,0)) -> Brandon Hawkins | C4: =VLOOKUP(B4,Worksheet!$A:$E,5,FALSE) -> 33 | E4: =INDEX(Worksheet!$A:$A,MATCH(LARGE(Worksheet!$D:$D,3),Worksheet!$D:$D,0)) -> Brandon Hawkins | F4: =VLOOKUP(E4,Worksheet!$A:$E,4,FALSE) -> 16474 | H4: =_xlfn.XLOOKUP(E4,'Part A'!$Q:$Q,'Part A'!$H:$H,0,0,1) -> jcb
B5: =INDEX(Worksheet!$A:$A,MATCH(LARGE(Worksheet!$E:$E,4),Worksheet!$E:$E,0)) -> Janet Bradley | C5: =VLOOKUP(B5,Worksheet!$A:$E,5,FALSE) -> 26 | E5: =INDEX(Worksheet!$A:$A,MATCH(LARGE(Worksheet!$D:$D,4),Worksheet!$D:$D,0)) -> Janet Bradley | F5: =VLOOKUP(E5,Worksheet!$A:$E,4,FALSE) -> 14270 | H5: =_xlfn.XLOOKUP(E5,'Part A'!$Q:$Q,'Part A'!$H:$H,0,0,1) -> solo
B6: =INDEX(Worksheet!$A:$A,MATCH(LARGE(Worksheet!$E:$E,5),Worksheet!$E:$E,0)) -> Phillip Simpson | C6: =VLOOKUP(B6,Worksheet!$A:$E,5,FALSE) -> 23 | E6: =INDEX(Worksheet!$A:$A,MATCH(LARGE(Worksheet!$D:$D,5),Worksheet!$D:$D,0)) -> Phillip Simpson | F6: =VLOOKUP(E6,Worksheet!$A:$E,4,FALSE) -> 11365 | H6: =_xlfn.XLOOKUP(E6,'Part A'!$Q:$Q,'Part A'!$H:$H,0,0,1) -> jcb
A10: Equations are also on Worksheet tab

Sheet Part D
A1: id | B1: first_name | C1: last_name | D1: email | E1: UserName | F1: CompanyName | G1: JobTitle | H1: gender | I1: Race | J1: purchase | K1: credit_card_type | L1: date | M1: State/Province | N1: City | O1: PostalCode | P1: Country | Q1: Month | R1: Month # | S1: Year
A2: 1021 | B2: Amy | C2: Jordan | D2: ajordank@ed.gov | E2: ajordank | F2: Fadeo | G2: Electrical Engineer | H2: Female | I2: Black or African American | J2: 755 | K2: china-unionpay | L2: 43101 | M2: Michigan | N2: Flint | O2: 48555 | P2: United States | Q2: =TEXT(Data_Set_3[[#This Row],[date]],"mmmm") -> January | R2: =MONTH(Data_Set_3[[#This Row],[date]]) -> 1 | S2: =YEAR(Data_Set_3[[#This Row],[date]]) -> 2018
A3: 1772 | B3: Harold | C3: Morris | D3: hmorrislf@is.gd | E3: hmorrislf | F3: Thoughtstorm | G3: Human Resources Assistant I | H3: Male | I3: Asian | J3: 390 | K3: jcb | L3: 43101 | M3: California | N3: San Luis Obispo | O3: 93407 | P3: United States | Q3: =TEXT(Data_Set_3[[#This Row],[date]],"mmmm") -> January | R3: =MONTH(Data_Set_3[[#This Row],[date]]) -> 1 | S3: =YEAR(Data_Set_3[[#This Row],[date]]) -> 2018
A4: 1524 | B4: Paul | C4: Rodriguez | D4: prodriguezej@businessweek.com | E4: prodriguezej | F4: Skiptube | G4: Librarian | H4: Male | I4: Thai | J4: 323 | K4: diners-club-international | L4: 43102 | M4: Virginia | N4: Richmond | O4: 23293 | P4: United States | Q4: =TEXT(Data_Set_3[[#This Row],[date]],"mmmm") -> January | R4: =MONTH(Data_Set_3[[#This Row],[date]]) -> 1 | S4: =YEAR(Data_Set_3[[#This Row],[date]]) -> 2018
A5: 1116 | B5: Christina | C5: Wheeler | D5: cwheeler37@ovh.net | E5: cwheeler37 | F5: Oozz | G5: Information Systems Manager | H5: Female | I5: Mexican | J5: 347 | K5: americanexpress | L5: 43106 | M5: Georgia | N5: Duluth | O5: 30096 | P5: United States | Q5: =TEXT(Data_Set_3[[#This Row],[date]],"mmmm") -> January | R5: =MONTH(Data_Set_3[[#This Row],[date]]) -> 1 | S5: =YEAR(Data_Set_3[[#This Row],[date]]) -> 2018
A6: 1234 | B6: Adam | C6: Jenkins | D6: ajenkins6h@comcast.net | E6: ajenkins6h | F6: Brightdog | G6: Internal Auditor | H6: Male | I6: White | J6: 917 | K6: maestro | L6: 43106 | M6: Texas | N6: Austin | O6: 78710 | P6: United States | Q6: =TEXT(Data_Set_3[[#This Row],[date]],"mmmm") -> January | R6: =MONTH(Data_Set_3[[#This Row],[date]]) -> 1 | S6: =YEAR(Data_Set_3[[#This Row],[date]]) -> 2018
A7: 1528 | B7: Bonnie | C7: Reyes | D7: breyesen@merriam-webster.com | E7: breyesen | F7: Jaxspan | G7: Clinical Specialist | H7: Female | I7: Korean | J7: 824 | K7: americanexpress | L7: 43108 | M7: California | N7: Van Nuys | O7: 91406 | P7: United States | Q7: =TEXT(Data_Set_3[[#This Row],[date]],"mmmm") -> January | R7: =MONTH(Data_Set_3[[#This Row],[date]]) -> 1 | S7: =YEAR(Data_Set_3[[#This Row],[date]]) -> 2018
A8: 1026 | B8: Jacqueline | C8: Ellis | D8: jellisp@imageshack.us | E8: jellisp | F8: Zoomdog | G8: Senior Sales Associate | H8: Female | I8: Black or African American | J8: 98 | K8: jcb | L8: 43110 | M8: New York | N8: Bronx | O8: 10469 | P8: United States | Q8: =TEXT(Data_Set_3[[#This Row],[date]],"mmmm") -> January | R8: =MONTH(Data_Set_3[[#This Row],[date]]) -> 1 | S8: =YEAR(Data_Set_3[[#This Row],[date]]) -> 2018
A9: 1489 | B9: Roger | C9: Matthews | D9: rmatthewsdk@nature.com | E9: rmatthewsdk | F9: Dabshots | G9: Environmental Tech | H9: Male | I9: Black or African American | J9: 224 | K9: maestro | L9: 43110 | M9: Virginia | N9: Hampton | O9: 23668 | P9: United States | Q9: =TEXT(Data_Set_3[[#This Row],[date]],"mmmm") -> January | R9: =MONTH(Data_Set_3[[#This Row],[date]]) -> 1 | S9: =YEAR(Data_Set_3[[#This Row],[date]]) -> 2018
A10: 1397 | B10: Evelyn | C10: Brooks | D10: ebrooksb0@tuttocitta.it | E10: ebrooksb0 | F10: BlogXS | G10: Web Designer IV | H10: Female | I10: Alaska Native | J10: 229 | K10: visa | L10: 43111 | M10: Iowa | N10: Cedar Rapids | O10: 52410 | P10: United States | Q10: =TEXT(Data_Set_3[[#This Row],[date]],"mmmm") -> January | R10: =MONTH(Data_Set_3[[#This Row],[date]]) -> 1 | S10: =YEAR(Data_Set_3[[#This Row],[date]]) -> 2018
A11: 1929 | B11: Walter | C11: Johnson | D11: wjohnsonps@columbia.edu | E11: wjohnsonps | F11: Demivee | G11: Payment Adjustment Coordinator | H11: Male | I11: American Indian | J11: 619 | K11: americanexpress | L11: 43111 | M11: Louisiana | N11: Lake Charles | O11: 70607 | P11: United States | Q11: =TEXT(Data_Set_3[[#This Row],[date]],"mmmm") -> January | R11: =MONTH(Data_Set_3[[#This Row],[date]]) -> 1 | S11: =YEAR(Data_Set_3[[#This Row],[date]]) -> 2018
A12: 1998 | B12: Christopher | C12: Stephens | D12: cstephensrp@myspace.com | E12: cstephensrp | F12: Meevee | G12: Marketing Assistant | H12: Male | I12: Hispanic | J12: 271 | K12: jcb | L12: 43113 | M12: Minnesota | N12: Saint Paul | O12: 55146 | P12: United States | Q12: =TEXT(Data_Set_3[[#This Row],[date]],"mmmm") -> January | R12: =MONTH(Data_Set_3[[#This Row],[date]]) -> 1 | S12: =YEAR(Data_Set_3[[#This Row],[date]]) -> 2018
A13: 1212 | B13: Patricia | C13: Weaver | D13: pweaver5v@merriam-webster.com | E13: pweaver5v | F13: Dablist | G13: Staff Accountant I | H13: Female | I13: White | J13: 208 | K13: mastercard | L13: 43116 | M13: Connecticut | N13: Hartford | O13: 6183 | P13: United States | Q13: =TEXT(Data_Set_3[[#This Row],[date]],"mmmm") -> January | R13: =MONTH(Data_Set_3[[#This Row],[date]]) -> 1 | S13: =YEAR(Data_Set_3[[#This Row],[date]]) -> 2018
... A1284: 1840 | B1284: Wayne | C1284: Mendoza | D1284: wmendozanb@constantcontact.com | E1284: wmendozanb | F1284: Feedmix | G1284: Recruiter | H1284: Male | I1284: Eskimo | J1284: 623 | K1284: jcb | L1284: 44923 | M1284: Indiana | N1284: Indianapolis | O1284: 46254 | P1284: United States | Q1284: =TEXT(Data_Set_3[[#This Row],[date]],"mmmm") -> December | R1284: =MONTH(Data_Set_3[[#This Row],[date]]) -> 12 | S1284: =YEAR(Data_Set_3[[#This Row],[date]]) -> 2022

Sheet Part E
A1: Part E #1 | L1: Part E #3 | O1: Part E #5 | Q1: Delaware had the highest average sales amount and New Hampshire had the least
A2: Year | B2: Total Sales | L2: Company | M2: Total Sales | O2: State | P2: Average Sales
A3: 2018 | B3: 130379 | L3: Linkbuzz | M3: 42023 | O3: Alabama | P3: 513.60606
A4: 2019 | B4: 122950 | L4: Thoughtmix | M4: 23274 | O4: Alaska | P4: 686.66667
A5: 2020 | B5: 106520 | L5: Rhynyx | M5: 22125 | O5: Arizona | P5: 543.59259
A6: 2021 | B6: 141307 | L6: Pixoboo | M6: 20306 | O6: Arkansas | P6: 285.66667
A7: 2022 | B7: 146698 | L7: Shufflester | M7: 20274 | O7: California | P7: 490.22727
A8: Grand Total | B8: 647854 | L8: Grand Total | M8: 128002 | O8: Colorado | P8: 520.81818
A9: 2018 had the least amount of sales while 2022 had the highest amount of sales | O9: Connecticut | P9: 390.7
L10: Part E #4 | O10: Delaware | P10: 927
L11: Credit Card Company | M11: Total Sales | O11: District of Columbia | P11: 508.71053
L12: jcb | M12: 220898 | O12: Florida | P12: 476.54839
A13: Part E # 2 | L13: maestro | M13: 77208 | O13: Georgia | P13: 556.31579
A14: Month | B14: Average Sales | L14: mastercard | M14: 64819 | O14: Hawaii | P14: 596.5
A15: January | B15: 483.11111 | L15: bankcard | M15: 60057 | O15: Idaho | P15: 528.875
A16: February | B16: 523.17 | L16: china-unionpay | M16: 58572 | O16: Illinois | P16: 525.15116
A17: March | B17: 464.91509 | L17: switch | M17: 29399 | O17: Indiana | P17: 565.3125
A18: April | B18: 482.94545 | L18: diners-club-carte-blanche | M18: 28845 | O18: Iowa | P18: 459
A19: May | B19: 571.9661 | L19: americanexpress | M19: 28033 | O19: Kansas | P19: 309.27273
A20: June | B20: 497.13592 | L20: laser | M20: 16533 | O20: Kentucky | P20: 513.52632
A21: July | B21: 478.47 | L21: visa-electron | M21: 15138 | O21: Louisiana | P21: 572.92308
A22: August | B22: 491.62295 | L22: diners-club-international | M22: 14523 | O22: Maryland | P22: 690.8
A23: September | B23: 528.59091 | L23: instapayment | M23: 9381 | O23: Massachusetts | P23: 534.9
A24: October | B24: 510.37755 | L24: visa | M24: 7991 | O24: Michigan | P24: 482.40909
A25: November | B25: 518.67961 | L25: diners-club-enroute | M25: 7697 | O25: Minnesota | P25: 545.65217
A26: December | B26: 503.31429 | L26: diners-club-us-ca | M26: 4737 | O26: Mississippi | P26: 591.33333
A27: Grand Total | B27: 504.95246 | L27: solo | M27: 4023 | O27: Missouri | P27: 582.05263
A28: May had the highest average of sales amount while March had the lowest | L28: Grand Total | M28: 647854 | O28: Montana | P28: 364
L29: jcb had the most amount of sales and solo had the least amount of sales | O29: Nebraska | P29: 519.125
A30: Part E #6 | O30: Nevada | P30: 490.94118
A31: My analsis shows that 2022 was the strongest year for total sales, with 2020 being the weakest. I can also see seasonal patterns for the average sales price, which dipped to the lowest in March and rose to the highest in May. The total sales by company showed one company on top by a large margin, which was Linkbuzz. Our top performing credit card company was jcb by a large margin with solo being the worst performing by total sales. The bottom of total sales by credit card company was much closer in sales amount. Lastly, our top performing state by average sales amount was Delaware and the lowest was New Hampshire. | O31: New Hampshire | P31: 99
O32: New Jersey | P32: 464.6
O33: New Mexico | P33: 608
O34: New York | P34: 451.65957
O35: North Carolina | P35: 528.36842
O36: North Dakota | P36: 456.33333
O37: Ohio | P37: 541.48333
O38: Oklahoma | P38: 408.33333
O39: Oregon | P39: 404.4
O40: Pennsylvania | P40: 490.52174
...

Sheet Data_Set_2
A1: id | B1: UserName | C1: CompanyName | D1: JobTitle
A2: 1 | B2: mmitchell0 | C2: Oba | D2: Professor
A3: 2 | B3: ghenry1 | C3: Bubbletube | D3: Safety Technician IV
A4: 3 | B4: lking2 | C4: Realpoint | D4: Electrical Engineer
A5: 4 | B5: dlopez3 | C5: Rhybox | D5: Office Assistant II
A6: 5 | B6: phayes4 | C6: Topicstorm | D6: Senior Financial Analyst
A7: 6 | B7: jreid5 | C7: Roodel | D7: Geologist II
A8: 7 | B8: hgilbert6 | C8: Skipfire | D8: Human Resources Assistant I
A9: 8 | B9: lpalmer7 | C9: Avaveo | D9: Social Worker
A10: 9 | B10: jmurray8 | C10: Wordtune | D10: Assistant Media Planner
A11: 10 | B11: ejones9 | C11: Skyvu | D11: Human Resources Assistant IV
A12: 11 | B12: slawsona | C12: Dablist | D12: Sales Associate
A13: 12 | B13: rhansenb | C13: Twitterwire | D13: Speech Pathologist
... A1001: 1000 | B1001: jwatsonrr | C1001: Buzzbean | D1001: Safety Technician I

Sheet Worksheet
A1: FullName | B1: Race | C1: Gender | D1: Sales Total Per Person | E1: # of Purchases
A2: Lois Fowler | B2: =_xlfn.XLOOKUP(A2,'Part A'!$Q:$Q,'Part A'!$F:$F,0,0,1) -> White | C2: =_xlfn.XLOOKUP(A2,'Part A'!$Q:$Q,'Part A'!$E:$E,0,0,1) -> Female | D2: =SUMIF('Part A'!$Q:$Q,A2,'Part A'!$G:$G) -> 15 | E2: =COUNTIF('Part A'!$Q:$Q,A2) -> 1
A3: Tammy Spencer | B3: =_xlfn.XLOOKUP(A3,'Part A'!$Q:$Q,'Part A'!$F:$F,0,0,1) -> Black or African American | C3: =_xlfn.XLOOKUP(A3,'Part A'!$Q:$Q,'Part A'!$E:$E,0,0,1) -> Female | D3: =SUMIF('Part A'!$Q:$Q,A3,'Part A'!$G:$G) -> 143 | E3: =COUNTIF('Part A'!$Q:$Q,A3) -> 1
A4: Douglas Daniels | B4: =_xlfn.XLOOKUP(A4,'Part A'!$Q:$Q,'Part A'!$F:$F,0,0,1) -> White | C4: =_xlfn.XLOOKUP(A4,'Part A'!$Q:$Q,'Part A'!$E:$E,0,0,1) -> Male | D4: =SUMIF('Part A'!$Q:$Q,A4,'Part A'!$G:$G) -> 747 | E4: =COUNTIF('Part A'!$Q:$Q,A4) -> 3
A5: Maria Hart | B5: =_xlfn.XLOOKUP(A5,'Part A'!$Q:$Q,'Part A'!$F:$F,0,0,1) -> South American | C5: =_xlfn.XLOOKUP(A5,'Part A'!$Q:$Q,'Part A'!$E:$E,0,0,1) -> Female | D5: =SUMIF('Part A'!$Q:$Q,A5,'Part A'!$G:$G) -> 410 | E5: =COUNTIF('Part A'!$Q:$Q,A5) -> 1
A6: Mary Ward | B6: =_xlfn.XLOOKUP(A6,'Part A'!$Q:$Q,'Part A'!$F:$F,0,0,1) -> Black or African American | C6: =_xlfn.XLOOKUP(A6,'Part A'!$Q:$Q,'Part A'!$E:$E,0,0,1) -> Female | D6: =SUMIF('Part A'!$Q:$Q,A6,'Part A'!$G:$G) -> 488 | E6: =COUNTIF('Part A'!$Q:$Q,A6) -> 1
A7: Rose Perez | B7: =_xlfn.XLOOKUP(A7,'Part A'!$Q:$Q,'Part A'!$F:$F,0,0,1) -> Black or African American | C7: =_xlfn.XLOOKUP(A7,'Part A'!$Q:$Q,'Part A'!$E:$E,0,0,1) -> Female | D7: =SUMIF('Part A'!$Q:$Q,A7,'Part A'!$G:$G) -> 11 | E7: =COUNTIF('Part A'!$Q:$Q,A7) -> 1
A8: Henry Warren | B8: =_xlfn.XLOOKUP(A8,'Part A'!$Q:$Q,'Part A'!$F:$F,0,0,1) -> Black or African American | C8: =_xlfn.XLOOKUP(A8,'Part A'!$Q:$Q,'Part A'!$E:$E,0,0,1) -> Male | D8: =SUMIF('Part A'!$Q:$Q,A8,'Part A'!$G:$G) -> 266 | E8: =COUNTIF('Part A'!$Q:$Q,A8) -> 1
A9: Janet Bradley | B9: =_xlfn.XLOOKUP(A9,'Part A'!$Q:$Q,'Part A'!$F:$F,0,0,1) -> Black or African American | C9: =_xlfn.XLOOKUP(A9,'Part A'!$Q:$Q,'Part A'!$E:$E,0,0,1) -> Female | D9: =SUMIF('Part A'!$Q:$Q,A9,'Part A'!$G:$G) -> 14270 | E9: =COUNTIF('Part A'!$Q:$Q,A9) -> 26
A10: Ernest Mills | B10: =_xlfn.XLOOKUP(A10,'Part A'!$Q:$Q,'Part A'!$F:$F,0,0,1) -> White | C10: =_xlfn.XLOOKUP(A10,'Part A'!$Q:$Q,'Part A'!$E:$E,0,0,1) -> Male | D10: =SUMIF('Part A'!$Q:$Q,A10,'Part A'!$G:$G) -> 574 | E10: =COUNTIF('Part A'!$Q:$Q,A10) -> 1
A11: Rachel Davis | B11: =_xlfn.XLOOKUP(A11,'Part A'!$Q:$Q,'Part A'!$F:$F,0,0,1) -> Asian | C11: =_xlfn.XLOOKUP(A11,'Part A'!$Q:$Q,'Part A'!$E:$E,0,0,1) -> Female | D11: =SUMIF('Part A'!$Q:$Q,A11,'Part A'!$G:$G) -> 575 | E11: =COUNTIF('Part A'!$Q:$Q,A11) -> 1
A12: Billy Henry | B12: =_xlfn.XLOOKUP(A12,'Part A'!$Q:$Q,'Part A'!$F:$F,0,0,1) -> White | C12: =_xlfn.XLOOKUP(A12,'Part A'!$Q:$Q,'Part A'!$E:$E,0,0,1) -> Male | D12: =SUMIF('Part A'!$Q:$Q,A12,'Part A'!$G:$G) -> 499 | E12: =COUNTIF('Part A'!$Q:$Q,A12) -> 1
A13: Teresa Morris | B13: =_xlfn.XLOOKUP(A13,'Part A'!$Q:$Q,'Part A'!$F:$F,0,0,1) -> White | C13: =_xlfn.XLOOKUP(A13,'Part A'!$Q:$Q,'Part A'!$E:$E,0,0,1) -> Female | D13: =SUMIF('Part A'!$Q:$Q,A13,'Part A'!$G:$G) -> 667 | E13: =COUNTIF('Part A'!$Q:$Q,A13) -> 1
... A559: Jeffrey Watson | B559: =_xlfn.XLOOKUP(A559,'Part A'!$Q:$Q,'Part A'!$F:$F,0,0,1) -> Black or African American | C559: =_xlfn.XLOOKUP(A559,'Part A'!$Q:$Q,'Part A'!$E:$E,0,0,1) -> Male | D559: =SUMIF('Part A'!$Q:$Q,A559,'Part A'!$G:$G) -> 38 | E559: =COUNTIF('Part A'!$Q:$Q,A559) -> 1
